I am trying to fix an error from a Python script.
Here is the tree structure of the project:
```bash
adamsl@DESKTOP-BKHEBT0:~/factory_design$ tree
.
├── LICENSE
├── factories
│   ├── LocalFileHandlerFactory.py
│   └── RemoteFileHandlerFactory.py
├── handlers
│   ├── FunctionHandler.py
│   ├── ReadFileHandler.py
│   └── WriteFileHandler.py
├── input_output
│   ├── FileReader.py
│   ├── FileWriter.py
│   ├── __init__.py
│   └── tests
│       ├── TestFileReader.py
│       └── TestFileWriter.py
└── interfaces
    └── FileHandlerFactory.py

5 directories, 12 files
adamsl@DESKTOP-BKHEBT0:~/factory_design$ 
```

Here is the source code from where the error is comming from:
```python
import os
import sys
sys.path.append( '/home/adamsl/factory_design/input_output/' )

from input_output import FileReader

class TestFileReader:
    def __init__(self, file_reader):
        self.file_reader = file_reader

    def execute(self):
        test_filename = 'test_file.txt'
        test_content = 'Hello, this is a test.'
        try:
            with open(test_filename, 'w') as file:
                file.write(test_content)
            
            read_content = self.file_reader.read(test_filename)
            assert read_content == test_content, "Test failed: Content does not match."
            print("Test passed: Content matches.")
        except AssertionError as e:
            print(f"Assertion Error: {e}")
        except Exception as e:
            print(f"An error occurred: {e}")
        finally:
            if os.path.exists(test_filename):
                try:
                    os.remove(test_filename)
                    if not os.path.exists(test_filename):
                        print("Cleanup successful: File removed.")
                    else:
                        print("Cleanup failed: File still exists.")
                except OSError as e:
                    print(f"Error removing file: {e}")



file_reader = FileReader()
tester = TestFileReader(file_reader)
tester.execute()
```

Here is the error message:
```error
adamsl@DESKTOP-BKHEBT0:~/factory_design$  /usr/bin/env /home/adamsl/agent_99/environment_for_agent_99/bin/python /home/adamsl/.vscode-server/extensions/ms-python.debugpy-2024.6.0-linux-x64/bundled/libs/debugpy/adapter/../../debugpy/launcher 54355 -- /home/adamsl/factory_design/input_output/tests/TestFileReader.py 
Traceback (most recent call last):
  File "/home/adamsl/.pyenv/versions/3.10.6/lib/python3.10/runpy.py", line 196, in _run_module_as_main
    return _run_code(code, main_globals, None,
  File "/home/adamsl/.pyenv/versions/3.10.6/lib/python3.10/runpy.py", line 86, in _run_code
    exec(code, run_globals)
  File "/home/adamsl/.vscode-server/extensions/ms-python.debugpy-2024.6.0-linux-x64/bundled/libs/debugpy/adapter/../../debugpy/launcher/../../debugpy/__main__.py", line 39, in <module>
    cli.main()
  File "/home/adamsl/.vscode-server/extensions/ms-python.debugpy-2024.6.0-linux-x64/bundled/libs/debugpy/adapter/../../debugpy/launcher/../../debugpy/../debugpy/server/cli.py", line 430, in main
    run()
  File "/home/adamsl/.vscode-server/extensions/ms-python.debugpy-2024.6.0-linux-x64/bundled/libs/debugpy/adapter/../../debugpy/launcher/../../debugpy/../debugpy/server/cli.py", line 284, in run_file
    runpy.run_path(target, run_name="__main__")
  File "/home/adamsl/.vscode-server/extensions/ms-python.debugpy-2024.6.0-linux-x64/bundled/libs/debugpy/_vendored/pydevd/_pydevd_bundle/pydevd_runpy.py", line 321, in run_path
    return _run_module_code(code, init_globals, run_name,
  File "/home/adamsl/.vscode-server/extensions/ms-python.debugpy-2024.6.0-linux-x64/bundled/libs/debugpy/_vendored/pydevd/_pydevd_bundle/pydevd_runpy.py", line 135, in _run_module_code
    _run_code(code, mod_globals, init_globals,
  File "/home/adamsl/.vscode-server/extensions/ms-python.debugpy-2024.6.0-linux-x64/bundled/libs/debugpy/_vendored/pydevd/_pydevd_bundle/pydevd_runpy.py", line 124, in _run_code
    exec(code, run_globals)
  File "/home/adamsl/factory_design/input_output/tests/TestFileReader.py", line 5, in <module>
    from input_output import FileReader
ModuleNotFoundError: No module named 'input_output'
adamsl@DESKTOP-BKHEBT0:~/factory_design$ tree
```

Please help me adjust the import for `input_output` so that the error is fixed.
